<?xml version="1.0" ?>
<!-- =================================================================================== -->
<!-- |    This document was autogenerated by xacro from /home/kortex/bak_proj/src/ocs2_fun/ocs2_spot_robot/urdf/spot_gazebo.urdf.xacro | -->
<!-- |    EDITING THIS FILE BY HAND IS NOT RECOMMENDED                                 | -->
<!-- =================================================================================== -->
<robot name="spot_w_arm" xmlns:xacro="http://ros.org/wiki/xacro">
    <xacro:include filename="$(find ocs2_arm)/urdf/camera_placement.xacro" />
    <xacro:include filename="$(find ocs2_arm)/urdf/camera_sensor.xacro" />
    <xacro:include filename="$(find ocs2_arm)/urdf/spot_transmission.xacro" />
    <link name="world" />
    <joint name="fixed" type="fixed">
        <parent link="world" />
        <child link="base" />
    </joint>
    <material name="silver">
        <color rgba="0.700 0.700 0.700 1.000" />
    </material>
    <link name="base">
        <visual>
            <origin rpy="0 0 0" xyz="0 0 0" />
            <geometry>
                <mesh filename="package://ocs2_robotic_assets/resources/spot/meshes/visual/body.dae" />
            </geometry>
            <material name="base">
                <color rgba="1 0.8431 0 1" />
            </material>
        </visual>
        <collision>
            <geometry>
                <box size="0.7 0.3 0.2" />
            </geometry>
        </collision>
        <inertial>
            <mass value="0.1" />
            <origin xyz="0 0 0" rpy="0 0 0" />
            <inertia ixx="0.03" iyy="0.03" izz="0.03" ixy="0.0" ixz="0.0" iyz="0.0" />
        </inertial>
    </link>
    <link name="base_inertia">
        <inertial>
            <origin rpy="0.0 0.0 0.0" xyz="0.006394396536052227 -9.812158532440662e-05 0.0009113792330026627" />
            <mass value="16.0" />
            <inertia ixx="0.017938806" ixy="0.00387963" ixz="0.001500772" iyy="0.370887745" iyz="6.8963e-05" izz="0.372497653" />
        </inertial>
    </link>
    <joint name="base_inertia_joint" type="fixed">
        <origin rpy="0 0 0" xyz="0 0 0" />
        <parent link="base" />
        <child link="base_inertia" />
    </joint>
    <link name="fl_hip">
        <visual>
            <origin rpy="0 0 0" xyz="0 0 0" />
            <geometry>
                <mesh filename="package://ocs2_robotic_assets/resources/spot/meshes/visual/fl_hip.dae" />
            </geometry>
        </visual>
        <inertial>
            <origin rpy="-0.716521349312305 0.02956473059648479 0.03655230014702582" xyz="-0.005374345928430557 0.012841847725212574 9.875232353806496e-05" />
            <mass value="2.0" />
            <inertia ixx="0.0030083333333333333" ixy="0.0" ixz="0.0" iyy="0.004320833333333334" iyz="0.0" izz="0.004320833333333334" />
        </inertial>
    </link>
    <joint name="LF_HAA" type="revolute">
        <origin rpy="0 0 0" xyz="0.29785 0.05500 0.00000" />
        <axis xyz="1 0 0" />
        <parent link="base" />
        <child link="fl_hip" />
        <limit effort="80" lower="-0.78539816339744827899" upper="0.78539816339744827899" velocity="7.5" />
    </joint>
    <link name="fl_uleg">
        <collision>
            <origin rpy="0 0 0" xyz="-0.0 0 -0.15" />
            <geometry>
                <cylinder length="0.3" radius="0.05" />
            </geometry>
        </collision>
        <visual>
            <origin rpy="0 0 0" xyz="0 0 0" />
            <geometry>
                <mesh filename="package://ocs2_robotic_assets/resources/spot/meshes/visual/fl_uleg.dae" />
            </geometry>
            <material name="fl_uleg">
                <color rgba="1 0.8431 0 1" />
            </material>
        </visual>
        <inertial>
            <origin rpy="-0.26437828203369795 -0.04853174570753804 0.024046963096353124" xyz="0.005142373498529196 -0.0024323679972440004 -0.12100915610790253" />
            <mass value="1.0" />
            <inertia ixx="0.01523333333333333" ixy="0.0" ixz="0.0" iyy="0.01523333333333333" iyz="0.0" izz="0.0010666666666666667" />
        </inertial>
    </link>
    <joint name="LF_HFE" type="revolute">
        <origin rpy="0 0 0" xyz="0.0 0.11080 0.0" />
        <axis xyz="0 1      0" />
        <parent link="fl_hip" />
        <child link="fl_uleg" />
        <limit effort="80" lower="-0.89884456477707963539" upper="2.2951079663725435509" velocity="7.5" />
    </joint>
    <link name="fl_lleg">
        <collision>
            <origin rpy="0 0 0" xyz="-0.0 0 -0.155" />
            <geometry>
                <cylinder length="0.30" radius="0.03" />
            </geometry>
        </collision>
        <visual>
            <origin rpy="0 0 0" xyz="0 0 0" />
            <geometry>
                <mesh filename="package://ocs2_robotic_assets/resources/spot/meshes/visual/fl_lleg.dae" />
            </geometry>
        </visual>
        <collision name="LF_FOOT_collision_sensor">
            <origin rpy="0 0 0" xyz="0 0 -0.335" />
            <geometry>
                <sphere radius="0.035" />
            </geometry>
        </collision>
        <inertial>
            <origin rpy="-0.007266925694167092 -0.009591807116834161 0.00035255970529224356" xyz="0.00225794012658298 4.607596201822162e-05 -0.1800822913646698" />
            <mass value="0.5" />
            <inertia ixx="0.007416666666666665" ixy="0.0" ixz="0.0" iyy="0.007416666666666665" iyz="0.0" izz="0.00013333333333333334" />
        </inertial>
    </link>
    <joint name="LF_KFE" type="revolute">
        <origin rpy="0 0 0" xyz="0.025 0.000 -0.3200" />
        <axis xyz="0 1 0" />
        <parent link="fl_uleg" />
        <child link="fl_lleg" />
        <limit effort="80" lower="-2.7929" upper="-0.254402" velocity="7.5" />
    </joint>
    <link name="LF_FOOT" />
    <joint name="LF_FOOT_JOINT" type="fixed">
        <origin rpy="0 0 0" xyz="-0.02 0.0 -0.370" />
        <parent link="fl_lleg" />
        <child link="LF_FOOT" />
    </joint>
    <link name="fr_hip">
        <visual>
            <origin rpy="0 0 0" xyz="0 0 0" />
            <geometry>
                <mesh filename="package://ocs2_robotic_assets/resources/spot/meshes/visual/fr_hip.dae" />
            </geometry>
            <material name="fr_hip">
                <color rgba="0.2 0.2 0.2 1" />
            </material>
        </visual>
        <inertial>
            <origin rpy="0.7165213493123055 -0.02956473059648479 0.03655230014702582" xyz="-0.005374345928430557 -0.012841847725212574 -9.875232353806496e-05" />
            <mass value="2.0" />
            <inertia ixx="0.0030083333333333333" ixy="0.0" ixz="0.0" iyy="0.004320833333333334" iyz="0.0" izz="0.004320833333333334" />
        </inertial>
    </link>
    <joint name="RF_HAA" type="revolute">
        <origin rpy="0 0 0" xyz="0.29785 -0.05500 0.00000" />
        <axis xyz="1 0 0" />
        <parent link="base" />
        <child link="fr_hip" />
        <limit effort="80" lower="-0.78539816339744827899" upper="0.78539816339744827899" velocity="7.5" />
    </joint>
    <link name="fr_uleg">
        <collision>
            <origin rpy="0 0 0" xyz="-0.0 0 -0.15" />
            <geometry>
                <cylinder length="0.3" radius="0.05" />
            </geometry>
        </collision>
        <visual>
            <origin rpy="0 0 0" xyz="0 0 0" />
            <geometry>
                <mesh filename="package://ocs2_robotic_assets/resources/spot/meshes/visual/fr_uleg.dae" />
            </geometry>
            <material name="fr_uleg">
                <color rgba="1 0.8431 0 1" />
            </material>
        </visual>
        <inertial>
            <origin rpy="0.2643905306958363 -0.04853174688302708 -0.024046943559834943" xyz="0.005142373498529196 0.0024323677644133568 -0.12100915610790253" />
            <mass value="1.0" />
            <inertia ixx="0.01523333333333333" ixy="0.0" ixz="0.0" iyy="0.01523333333333333" iyz="0.0" izz="0.0010666666666666667" />
        </inertial>
    </link>
    <joint name="RF_HFE" type="revolute">
        <origin rpy="0 0 0" xyz="0.0 -0.11080 0.0" />
        <axis xyz="0  1      0" />
        <parent link="fr_hip" />
        <child link="fr_uleg" />
        <limit effort="80" lower="-0.89884456477707963539" upper="2.2951079663725435509" velocity="7.5" />
    </joint>
    <link name="fr_lleg">
        <collision>
            <origin rpy="0 0 0" xyz="-0.0 0 -0.155" />
            <geometry>
                <cylinder length="0.30" radius="0.03" />
            </geometry>
        </collision>
        <visual>
            <origin rpy="0 0 0" xyz="0 0 0" />
            <geometry>
                <mesh filename="package://ocs2_robotic_assets/resources/spot/meshes/visual/fr_lleg.dae" />
            </geometry>
        </visual>
        <collision name="RF_FOOT_collision_sensor">
            <origin rpy="0 0 0" xyz="0 0 -0.335" />
            <geometry>
                <sphere radius="0.035" />
            </geometry>
        </collision>
        <inertial>
            <origin rpy="-0.007266925694167092 -0.009591807116834161 0.00035255970529224356" xyz="0.00225794012658298 4.607596201822162e-05 -0.1800822913646698" />
            <mass value="0.5" />
            <inertia ixx="0.007416666666666665" ixy="0.0" ixz="0.0" iyy="0.007416666666666665" iyz="0.0" izz="0.00013333333333333334" />
        </inertial>
    </link>
    <joint name="RF_KFE" type="revolute">
        <origin rpy="0 0 0" xyz="0.025 0.000 -0.3200" />
        <axis xyz="0 1 0" />
        <parent link="fr_uleg" />
        <child link="fr_lleg" />
        <limit effort="80" lower="-2.7929" upper="-0.254402" velocity="7.5" />
    </joint>
    <link name="RF_FOOT" />
    <joint name="RF_FOOT_JOINT" type="fixed">
        <origin rpy="0 0 0" xyz="-0.02 0.0 -0.370" />
        <parent link="fr_lleg" />
        <child link="RF_FOOT" />
    </joint>
    <link name="hl_hip">
        <visual>
            <origin rpy="0 0 0" xyz="0 0 0" />
            <geometry>
                <mesh filename="package://ocs2_robotic_assets/resources/spot/meshes/visual/hl_hip.dae" />
            </geometry>
            <material name="hl_hip">
                <color rgba="0.2 0.2 0.2 1" />
            </material>
        </visual>
        <inertial>
            <origin rpy="0.7165213493123055 0.02956473059648479 -0.03655230014702582" xyz="0.005374345928430557 0.012841847725212574 -9.875232353806496e-05" />
            <mass value="2.0" />
            <inertia ixx="0.0030083333333333333" ixy="0.0" ixz="0.0" iyy="0.004320833333333334" iyz="0.0" izz="0.004320833333333334" />
        </inertial>
    </link>
    <joint name="LH_HAA" type="revolute">
        <origin rpy="0 0 0" xyz="-0.29785 0.05500 0.00000" />
        <axis xyz="1 0 0" />
        <parent link="base" />
        <child link="hl_hip" />
        <limit effort="80" lower="-0.78539816339744827899" upper="0.78539816339744827899" velocity="7.5" />
    </joint>
    <link name="hl_uleg">
        <collision>
            <origin rpy="0 0 0" xyz="-0.0 0 -0.15" />
            <geometry>
                <cylinder length="0.3" radius="0.05" />
            </geometry>
        </collision>
        <visual>
            <origin rpy="0 0 0" xyz="0 0 0" />
            <geometry>
                <mesh filename="package://ocs2_robotic_assets/resources/spot/meshes/visual/hl_uleg.dae" />
            </geometry>
            <material name="hl_uleg">
                <color rgba="1 0.8431 0 1" />
            </material>
        </visual>
        <inertial>
            <origin rpy="-0.26437828203369795 -0.04853174570753804 0.024046963096353124" xyz="0.005142373498529196 -0.0024323679972440004 -0.12100915610790253" />
            <mass value="1.0" />
            <inertia ixx="0.01523333333333333" ixy="0.0" ixz="0.0" iyy="0.01523333333333333" iyz="0.0" izz="0.0010666666666666667" />
        </inertial>
    </link>
    <joint name="LH_HFE" type="revolute">
        <origin rpy="0 0 0" xyz="0.0 0.11080 0.0" />
        <axis xyz="0 1      0" />
        <parent link="hl_hip" />
        <child link="hl_uleg" />
        <limit effort="80" lower="-0.89884456477707963539" upper="2.2951079663725435509" velocity="7.5" />
    </joint>
    <link name="hl_lleg">
        <collision>
            <origin rpy="0 0 0" xyz="-0.0 0 -0.155" />
            <geometry>
                <cylinder length="0.30" radius="0.03" />
            </geometry>
        </collision>
        <visual>
            <origin rpy="0 0 0" xyz="0 0 0" />
            <geometry>
                <mesh filename="package://ocs2_robotic_assets/resources/spot/meshes/visual/hl_lleg.dae" />
            </geometry>
        </visual>
        <collision name="LH_FOOT_collision_sensor">
            <origin rpy="0 0 0" xyz="0 0 -0.335" />
            <geometry>
                <sphere radius="0.035" />
            </geometry>
        </collision>
        <inertial>
            <origin rpy="-0.007266925694167092 -0.009591807116834161 0.00035255970529224356" xyz="0.00225794012658298 4.607596201822162e-05 -0.1800822913646698" />
            <mass value="0.5" />
            <inertia ixx="0.007416666666666665" ixy="0.0" ixz="0.0" iyy="0.007416666666666665" iyz="0.0" izz="0.00013333333333333334" />
        </inertial>
    </link>
    <joint name="LH_KFE" type="revolute">
        <origin rpy="0 0 0" xyz="0.025 0.000 -0.3200" />
        <axis xyz="0 1 0" />
        <parent link="hl_uleg" />
        <child link="hl_lleg" />
        <limit effort="80" lower="-2.7929" upper="-0.254402" velocity="7.5" />
    </joint>
    <link name="LH_FOOT" />
    <joint name="LH_FOOT_JOINT" type="fixed">
        <origin rpy="0 0 0" xyz="-0.02 0.0 -0.370" />
        <parent link="hl_lleg" />
        <child link="LH_FOOT" />
    </joint>
    <link name="hr_hip">
        <visual>
            <origin rpy="0 0 0" xyz="0 0 0" />
            <geometry>
                <mesh filename="package://ocs2_robotic_assets/resources/spot/meshes/visual/hr_hip.dae" />
            </geometry>
            <material name="hr_hip">
                <color rgba="0.2 0.2 0.2 1" />
            </material>
        </visual>
        <inertial>
            <origin rpy="-0.716521349312305 -0.02956473059648479 -0.03655230014702582" xyz="0.005374345928430557 -0.012841847725212574 9.875232353806496e-05" />
            <mass value="2.0" />
            <inertia ixx="0.0030083333333333333" ixy="0.0" ixz="0.0" iyy="0.004320833333333334" iyz="0.0" izz="0.004320833333333334" />
        </inertial>
    </link>
    <joint name="RH_HAA" type="revolute">
        <origin rpy="0 0 0" xyz="-0.29785 -0.05500 0.00000" />
        <axis xyz="1 0 0" />
        <parent link="base" />
        <child link="hr_hip" />
        <limit effort="80" lower="-0.78539816339744827899" upper="0.78539816339744827899" velocity="7.5" />
    </joint>
    <link name="hr_uleg">
        <collision>
            <origin rpy="0 0 0" xyz="-0.0 0 -0.15" />
            <geometry>
                <cylinder length="0.3" radius="0.05" />
            </geometry>
        </collision>
        <visual>
            <origin rpy="0 0 0" xyz="0 0 0" />
            <geometry>
                <mesh filename="package://ocs2_robotic_assets/resources/spot/meshes/visual/hr_uleg.dae" />
            </geometry>
            <material name="hr_uleg">
                <color rgba="1 0.8431 0 1" />
            </material>
        </visual>
        <inertial>
            <origin rpy="0.2643905306958363 -0.04853174688302708 -0.024046943559834943" xyz="0.005142373498529196 0.0024323677644133568 -0.12100915610790253" />
            <mass value="1.0" />
            <inertia ixx="0.01523333333333333" ixy="0.0" ixz="0.0" iyy="0.01523333333333333" iyz="0.0" izz="0.0010666666666666667" />
        </inertial>
    </link>
    <joint name="RH_HFE" type="revolute">
        <origin rpy="0 0 0" xyz="0.0 -0.11080 0.0" />
        <axis xyz="0  1      0" />
        <parent link="hr_hip" />
        <child link="hr_uleg" />
        <limit effort="80" lower="-0.89884456477707963539" upper="2.2951079663725435509" velocity="7.5" />
    </joint>
    <link name="hr_lleg">
        <collision>
            <origin rpy="0 0 0" xyz="-0.0 0 -0.155" />
            <geometry>
                <cylinder length="0.30" radius="0.03" />
            </geometry>
        </collision>
        <visual>
            <origin rpy="0 0 0" xyz="0 0 0" />
            <geometry>
                <mesh filename="package://ocs2_robotic_assets/resources/spot/meshes/visual/hr_lleg.dae" />
            </geometry>
        </visual>
        <collision name="RH_FOOT_collision_sensor">
            <origin rpy="0 0 0" xyz="0 0 -0.335" />
            <geometry>
                <sphere radius="0.035" />
            </geometry>
        </collision>
        <inertial>
            <origin rpy="-0.007266925694167092 -0.009591807116834161 0.00035255970529224356" xyz="0.00225794012658298 4.607596201822162e-05 -0.1800822913646698" />
            <mass value="0.5" />
            <inertia ixx="0.007416666666666665" ixy="0.0" ixz="0.0" iyy="0.007416666666666665" iyz="0.0" izz="0.00013333333333333334" />
        </inertial>
    </link>
    <joint name="RH_KFE" type="revolute">
        <origin rpy="0 0 0" xyz="0.025 0.000 -0.3200" />
        <axis xyz="0 1 0" />
        <parent link="hr_uleg" />
        <child link="hr_lleg" />
        <limit effort="80" lower="-2.7929" upper="-0.254402" velocity="7.5" />
    </joint>
    <link name="RH_FOOT" />
    <joint name="RH_FOOT_JOINT" type="fixed">
        <origin rpy="0 0 0" xyz="-0.02 0.0 -0.370" />
        <parent link="hr_lleg" />
        <child link="RH_FOOT" />
    </joint>
    <!-- CAMERAS -->
    <!-- Camera - front right -->
    <xacro:spot_cam_link name="camera_link_frontright" />
    <xacro:spot_cam_joint name="camera_joint_frontright" origin_xyz="0.415 -0.037 -0.01" origin_rpy="-1.355558 0.353917 0.554196" parent_link="base" child_link="camera_link_frontright" />
    <xacro:spot_cam_link name="camera_optical_frontright" />
    <xacro:spot_cam_joint name="camera_optical_joint_frontright" origin_xyz="0 0 0" origin_rpy="-1.57 0 -1.57" parent_link="camera_link_frontright" child_link="camera_optical_frontright" />
    <!-- Camera - front left -->
    <xacro:spot_cam_link name="camera_link_frontleft" />
    <xacro:spot_cam_joint name="camera_joint_frontleft" origin_xyz="0.415 0.037 -0.01" origin_rpy="1.355558 0.353917 -0.554196" parent_link="base" child_link="camera_link_frontleft" />
    <xacro:spot_cam_link name="camera_optical_frontleft" />
    <xacro:spot_cam_joint name="camera_optical_joint_frontleft" origin_xyz="0 0 0" origin_rpy="-1.57 0 -1.57" parent_link="camera_link_frontleft" child_link="camera_optical_frontleft" />
    <!-- Camera - right -->
    <xacro:spot_cam_link name="camera_link_right" />
    <xacro:spot_cam_joint name="camera_joint_right" origin_xyz="-0.125 -0.12 0.035" origin_rpy="3.141592653589793 0.2 -1.5707963267948966" parent_link="base" child_link="camera_link_right" />
    <xacro:spot_cam_link name="camera_optical_right" />
    <xacro:spot_cam_joint name="camera_optical_joint_right" origin_xyz="0 0 0" origin_rpy="-1.57 0 -1.57" parent_link="camera_link_right" child_link="camera_optical_right" />
    <!-- Camera - left -->
    <xacro:spot_cam_link name="camera_link_left" />
    <xacro:spot_cam_joint name="camera_joint_left" origin_xyz="-0.125 0.12 0.035" origin_rpy="3.141592653589793 0.2 1.5707963267948966" parent_link="base" child_link="camera_link_left" />
    <xacro:spot_cam_link name="camera_optical_left" />
    <xacro:spot_cam_joint name="camera_optical_joint_left" origin_xyz="0 0 0" origin_rpy="-1.57 0 -1.57" parent_link="camera_link_left" child_link="camera_optical_left" />
    <!-- Camera - back -->
    <xacro:spot_cam_link name="camera_link_back" />
    <xacro:spot_cam_joint name="camera_joint_back" origin_xyz="-0.425 0 0.01" origin_rpy="0 0.3 -3.141592653589793" parent_link="base" child_link="camera_link_back" />
    <xacro:spot_cam_link name="camera_optical_back" />
    <xacro:spot_cam_joint name="camera_optical_joint_back" origin_xyz="0 0 0" origin_rpy="-1.57 0 -1.57" parent_link="camera_link_back" child_link="camera_optical_back" />
    <!-- Front right camera -->
    <!-- Front right depth camera -->
    <xacro:spot_cam_sensor name="frontright" />
    <!-- Front left camera -->
    <!-- Front left depth camera -->
    <xacro:spot_cam_sensor name="frontleft" />
    <!-- Right camera -->
    <!-- Right depth camera -->
    <xacro:spot_cam_sensor name="right" />
    <!-- Left camera -->
    <!-- Left depth camera -->
    <xacro:spot_cam_sensor name="left" />
    <!-- Back camera -->
    <!-- Back left depth camera -->
    <xacro:spot_cam_sensor name="back" />
    <!-- Spot Arm -->
    <!-- =================================================================================== -->
    <!-- |    This document was autogenerated by xacro from spot_arm.xacro                 | -->
    <!-- |    EDITING THIS FILE BY HAND IS NOT RECOMMENDED                                 | -->
    <!-- =================================================================================== -->
    <!-- =================================================================================== -->
    <!-- |    This document was autogenerated by xacro from spot_arm.xacro                 | -->
    <!-- |    EDITING THIS FILE BY HAND IS NOT RECOMMENDED                                 | -->
    <!-- =================================================================================== -->
    <link name="Part3_1">
        <inertial>
            <origin rpy="0 0 0" xyz="-0.00911464892336129 0.12606054498393937 5.551115123125783e-17" />
            <mass value="1.95245995004642" />
            <inertia ixx="0.066789" ixy="0.011971" ixz="-0.0" iyy="0.014993" iyz="0.0" izz="0.071949" />
        </inertial>
        <visual>
            <origin rpy="0 0 0" xyz="0.001 -0.4505 -0.0475" />
            <geometry>
                <mesh filename="package://ocs2_robotic_assets/resources/spot/meshes/visual/Part3_1.stl" scale="0.001 0.001 0.001" />
            </geometry>
            <material name="silver" />
        </visual>
        <collision>
            <origin rpy="0 0 0" xyz="0.001 -0.4505 -0.0475" />
            <geometry>
                <mesh filename="package://ocs2_robotic_assets/resources/spot/meshes/visual/Part3_1.stl" scale="0.001 0.001 0.001" />
            </geometry>
        </collision>
    </link>
    <link name="gripper_1">
        <inertial>
            <origin rpy="0 0 0" xyz="-8.366123908053191e-08 0.07051371901138614 0.017123167388316526" />
            <mass value="0.59780007036604434" />
            <inertia ixx="0.01723" ixy="0.0" ixz="0.0" iyy="0.00734" iyz="-0.003871" izz="0.0153" />
        </inertial>
        <visual>
            <origin rpy="0 0 0" xyz="0.0085 -0.77959 -0.0475" />
            <geometry>
                <mesh filename="package://ocs2_robotic_assets/resources/spot/meshes/visual/gripper_1.stl" scale="0.001 0.001 0.001" />
            </geometry>
            <material name="silver" />
        </visual>
        <collision>
            <origin rpy="0 0 0" xyz="0.0085 -0.77959 -0.0475" />
            <geometry>
                <mesh filename="package://ocs2_robotic_assets/resources/spot/meshes/visual/gripper_1.stl" scale="0.001 0.001 0.001" />
            </geometry>
        </collision>
    </link>
    <link name="finger_1">
        <inertial>
            <origin rpy="0 0 0" xyz="0.8635899028063472 0.09862056591557622 0.00850232975194119" />
            <mass value="0.171236178687828" />
            <inertia ixx="0.002129" ixy="0.0" ixz="-0.0" iyy="0.001681" iyz="0.000162" izz="0.003403" />
        </inertial>
        <visual>
            <origin rpy="0 0 0" xyz="0.87709 -0.823505 -0.0185" />
            <geometry>
                <mesh filename="package://ocs2_robotic_assets/resources/spot/meshes/visual/finger_1.stl" scale="0.001 0.001 0.001" />
            </geometry>
            <material name="silver" />
        </visual>
        <collision>
            <origin rpy="0 0 0" xyz="0.87709 -0.823505 -0.0185" />
            <geometry>
                <mesh filename="package://ocs2_robotic_assets/resources/spot/meshes/visual/finger_1.stl" scale="0.001 0.001 0.001" />
            </geometry>
        </collision>
    </link>
    <link name="Part1_1">
        <inertial>
            <origin rpy="0 0 0" xyz="-0.0163095589512068 0.17540914221218962 0.0" />
            <mass value="1.2658281999999998" />
            <inertia ixx="0.12979" ixy="0.002625" ixz="0.0" iyy="0.01004" iyz="0.0" izz="0.129493" />
        </inertial>
        <visual>
            <origin rpy="0 0 0" xyz="-0.015 -0.0 -0.115" />
            <geometry>
                <mesh filename="package://ocs2_robotic_assets/resources/spot/meshes/visual/Part1_1.stl" scale="0.001 0.001 0.001" />
            </geometry>
            <material name="silver" />
        </visual>
        <collision>
            <origin rpy="0 0 0" xyz="-0.015 -0.0 -0.115" />
            <geometry>
                <mesh filename="package://ocs2_robotic_assets/resources/spot/meshes/visual/Part1_1.stl" scale="0.001 0.001 0.001" />
            </geometry>
        </collision>
    </link>
    <link name="Part0_1">
        <inertial>
            <origin rpy="0 0 0" xyz="0.05071972800114364 -1.0308563411658574e-17 0.04676911608650795" />
            <mass value="0.6925827706354272" />
            <inertia ixx="0.01241" ixy="-0.0" ixz="-0.001047" iyy="0.010387" iyz="0.0" izz="0.012306" />
        </inertial>
        <visual>
            <origin rpy="0 0 0" xyz="-0.0 -0.0 -0.065" />
            <geometry>
                <mesh filename="package://ocs2_robotic_assets/resources/spot/meshes/visual/Part0_1.stl" scale="0.001 0.001 0.001" />
            </geometry>
            <material name="silver" />
        </visual>
        <collision>
            <origin rpy="0 0 0" xyz="-0.0 -0.0 -0.065" />
            <geometry>
                <mesh filename="package://ocs2_robotic_assets/resources/spot/meshes/visual/Part0_1.stl" scale="0.001 0.001 0.001" />
            </geometry>
        </collision>
    </link>
    <link name="Part4_1">
        <inertial>
            <origin rpy="0 0 0" xyz="0.03954999709763633 0.03472006124891969 4.209155544249166e-08" />
            <mass value="0.32278801394086396" />
            <inertia ixx="0.00339" ixy="-2.1e-05" ixz="0.0" iyy="0.002242" iyz="-0.0" izz="0.003439" />
        </inertial>
        <visual>
            <origin rpy="0 0 0" xyz="0.0485 -0.69859 -0.0475" />
            <geometry>
                <mesh filename="package://ocs2_robotic_assets/resources/spot/meshes/visual/Part4_1.stl" scale="0.001 0.001 0.001" />
            </geometry>
            <material name="silver" />
        </visual>
        <collision>
            <origin rpy="0 0 0" xyz="0.0485 -0.69859 -0.0475" />
            <geometry>
                <mesh filename="package://ocs2_robotic_assets/resources/spot/meshes/visual/Part4_1.stl" scale="0.001 0.001 0.001" />
            </geometry>
        </collision>
    </link>
    <link name="Part2_1">
        <inertial>
            <origin rpy="0 0 0" xyz="-0.015621881612358529 0.06665620790957599 -0.058074231003688394" />
            <mass value="0.7368455487741179" />
            <inertia ixx="0.018073" ixy="0.000915" ixz="-0.00101" iyy="0.011789" iyz="0.003728" izz="0.01667" />
        </inertial>
        <visual>
            <origin rpy="0 0 0" xyz="-0.017 -0.3125 -0.115" />
            <geometry>
                <mesh filename="package://ocs2_robotic_assets/resources/spot/meshes/visual/Part2_1.stl" scale="0.001 0.001 0.001" />
            </geometry>
            <material name="silver" />
        </visual>
        <collision>
            <origin rpy="0 0 0" xyz="-0.017 -0.3125 -0.115" />
            <geometry>
                <mesh filename="package://ocs2_robotic_assets/resources/spot/meshes/visual/Part2_1.stl" scale="0.001 0.001 0.001" />
            </geometry>
        </collision>
    </link>
    <joint name="Rev3" type="revolute">
        <origin rpy="0 0 0" xyz="-0.018 0.138 -0.0675" />
        <parent link="Part2_1" />
        <child link="Part3_1" />
        <axis xyz="0.0 1.0 0.0" />
        <limit effort="100" lower="-2.879793" upper="2.879793" velocity="100" />
    </joint>
    <joint name="Rev6" type="revolute">
        <origin rpy="0 0 0" xyz="0.04 0.081 0.0" />
        <parent link="Part4_1" />
        <child link="gripper_1" />
        <axis xyz="-0.0 1.0 0.0" />
        <limit effort="100" lower="-2.96706" upper="2.96706" velocity="100" />
    </joint>
    <joint name="Rev7" type="revolute">
        <origin rpy="0 0 0" xyz="-0.86859 0.043915 -0.029" />
        <parent link="gripper_1" />
        <child link="finger_1" />
        <axis xyz="1.0 -0.0 0.0" />
        <limit effort="100" lower="-1.396263" upper="0.349066" velocity="100" />
    </joint>
    <joint name="Rev8" type="revolute">
        <origin rpy="0 0 0" xyz="0.015 0.0 0.05" />
        <parent link="Part0_1" />
        <child link="Part1_1" />
        <axis xyz="-1.0 0.0 0.0" />
        <limit effort="100" lower="-3.665191" upper="0.0" velocity="100" />
    </joint>
    <joint name="Rev9" type="revolute">
        <origin rpy="0 0 0" xyz="0.29 0.0 0.081" />
        <parent link="base" />
        <child link="Part0_1" />
        <axis xyz="0.0 0.0 1.0" />
        <limit effort="100" lower="-3.141593" upper="2.617994" velocity="100" />
    </joint>
    <joint name="Rev10" type="revolute">
        <origin rpy="0 0 0" xyz="-0.0475 0.24809 0.0" />
        <parent link="Part3_1" />
        <child link="Part4_1" />
        <axis xyz="1.0 0.0 0.0" />
        <limit effort="100" lower="-1.570796" upper="1.570796" velocity="100" />
    </joint>
    <joint name="Rev11" type="revolute">
        <origin rpy="0 0 0" xyz="0.002 0.3125 0.0" />
        <parent link="Part1_1" />
        <child link="Part2_1" />
        <axis xyz="1.0 0.0 0.0" />
        <limit effort="100" lower="0.0" upper="2.96706" velocity="100" />
    </joint>
    <xacro:transmission name="trans_LF_HAA" joint="LF_HAA" actuator="motor_LFHAA" />
    <xacro:transmission name="trans_LH_HAA" joint="LH_HAA" actuator="motor_LH_HAA" />
    <xacro:transmission name="trans_RF_HAA" joint="RF_HAA" actuator="motor_RF_HAA" />
    <xacro:transmission name="trans_RH_HAA" joint="RH_HAA" actuator="motor_RH_HAA" />
    <xacro:transmission name="trans_Rev9" joint="Rev9" actuator="motor_Rev9" />
    <xacro:transmission name="trans_LF_HFE" joint="LF_HFE" actuator="motor_LF_HFE" />
    <xacro:transmission name="trans_LH_HFE" joint="LH_HFE" actuator="motor_LH_HFE" />
    <xacro:transmission name="trans_RF_HFE" joint="RF_HFE" actuator="motor_RF_HFE" />
    <xacro:transmission name="trans_RH_HFE" joint="RH_HFE" actuator="motor_RH_HFE" />
    <xacro:transmission name="trans_Rev8" joint="Rev8" actuator="motor_Rev8" />
    <xacro:transmission name="trans_LF_KFE" joint="LF_KFE" actuator="motor_LF_KFE" />
    <xacro:transmission name="trans_LH_KFE" joint="LH_KFE" actuator="motor_LH_KFE" />
    <xacro:transmission name="trans_RF_KFE" joint="RF_KFE" actuator="motor_RF_KFE" />
    <xacro:transmission name="trans_RH_KFE" joint="RH_KFE" actuator="motor_RH_KFE" />
    <xacro:transmission name="trans_Rev11" joint="Rev11" actuator="motor_Rev11" />
    <xacro:transmission name="trans_Rev3" joint="Rev3" actuator="motor_Rev3" />
    <xacro:transmission name="trans_Rev10" joint="Rev10" actuator="motor_Rev10" />
    <xacro:transmission name="trans_Rev6" joint="Rev6" actuator="motor_Rev6" />
    <xacro:transmission name="trans_Rev7" joint="Rev7" actuator="motor_Rev7" />
    <gazebo>
        <plugin name="gazebo_ros_control" filename="libgazebo_ros_control.so">
            <robotNamespace>/spot_w_arm</robotNamespace>
        </plugin>
    </gazebo>
    <transmission name="trans_LF_HAA">
        <type>transmission_interface/SimpleTransmission</type>
        <joint name="LF_HAA">
            <hardwareInterface>hardware_interface/EffortJointInterface</hardwareInterface>
        </joint>
        <actuator name="LF_HAA_motor">
            <hardwareInterface>hardware_interface/EffortJointInterface</hardwareInterface>
            <mechanicalReduction>1</mechanicalReduction>
        </actuator>
    </transmission>
    <transmission name="trans_LF_HFE">
        <type>transmission_interface/SimpleTransmission</type>
        <joint name="LF_HFE">
            <hardwareInterface>hardware_interface/EffortJointInterface</hardwareInterface>
        </joint>
        <actuator name="LF_HFE_motor">
            <hardwareInterface>hardware_interface/EffortJointInterface</hardwareInterface>
            <mechanicalReduction>1</mechanicalReduction>
        </actuator>
    </transmission>
    <transmission name="trans_LF_KFE">
        <type>transmission_interface/SimpleTransmission</type>
        <joint name="LF_KFE">
            <hardwareInterface>hardware_interface/EffortJointInterface</hardwareInterface>
        </joint>
        <actuator name="LF_KFE_motor">
            <hardwareInterface>hardware_interface/EffortJointInterface</hardwareInterface>
            <mechanicalReduction>1</mechanicalReduction>
        </actuator>
    </transmission>
    <transmission name="trans_RF_HAA">
        <type>transmission_interface/SimpleTransmission</type>
        <joint name="RF_HAA">
            <hardwareInterface>hardware_interface/EffortJointInterface</hardwareInterface>
        </joint>
        <actuator name="RF_HAA_motor">
            <hardwareInterface>hardware_interface/EffortJointInterface</hardwareInterface>
            <mechanicalReduction>1</mechanicalReduction>
        </actuator>
    </transmission>
    <transmission name="trans_RF_HFE">
        <type>transmission_interface/SimpleTransmission</type>
        <joint name="RF_HFE">
            <hardwareInterface>hardware_interface/EffortJointInterface</hardwareInterface>
        </joint>
        <actuator name="RF_HFE_motor">
            <hardwareInterface>hardware_interface/EffortJointInterface</hardwareInterface>
            <mechanicalReduction>1</mechanicalReduction>
        </actuator>
    </transmission>
    <transmission name="trans_RF_KFE">
        <type>transmission_interface/SimpleTransmission</type>
        <joint name="RF_KFE">
            <hardwareInterface>hardware_interface/EffortJointInterface</hardwareInterface>
        </joint>
        <actuator name="RF_KFE_motor">
            <hardwareInterface>hardware_interface/EffortJointInterface</hardwareInterface>
            <mechanicalReduction>1</mechanicalReduction>
        </actuator>
    </transmission>
    <transmission name="trans_LH_HAA">
        <type>transmission_interface/SimpleTransmission</type>
        <joint name="LH_HAA">
            <hardwareInterface>hardware_interface/EffortJointInterface</hardwareInterface>
        </joint>
        <actuator name="LH_HAA_motor">
            <hardwareInterface>hardware_interface/EffortJointInterface</hardwareInterface>
            <mechanicalReduction>1</mechanicalReduction>
        </actuator>
    </transmission>
    <transmission name="trans_LH_HFE">
        <type>transmission_interface/SimpleTransmission</type>
        <joint name="LH_HFE">
            <hardwareInterface>hardware_interface/EffortJointInterface</hardwareInterface>
        </joint>
        <actuator name="LH_HFE_motor">
            <hardwareInterface>hardware_interface/EffortJointInterface</hardwareInterface>
            <mechanicalReduction>1</mechanicalReduction>
        </actuator>
    </transmission>
    <transmission name="trans_LH_KFE">
        <type>transmission_interface/SimpleTransmission</type>
        <joint name="LH_KFE">
            <hardwareInterface>hardware_interface/EffortJointInterface</hardwareInterface>
        </joint>
        <actuator name="LH_KFE_motor">
            <hardwareInterface>hardware_interface/EffortJointInterface</hardwareInterface>
            <mechanicalReduction>1</mechanicalReduction>
        </actuator>
    </transmission>
    <transmission name="trans_RH_HAA">
        <type>transmission_interface/SimpleTransmission</type>
        <joint name="RH_HAA">
            <hardwareInterface>hardware_interface/EffortJointInterface</hardwareInterface>
        </joint>
        <actuator name="RH_HAA_motor">
            <hardwareInterface>hardware_interface/EffortJointInterface</hardwareInterface>
            <mechanicalReduction>1</mechanicalReduction>
        </actuator>
    </transmission>
    <transmission name="trans_RH_HFE">
        <type>transmission_interface/SimpleTransmission</type>
        <joint name="RH_HFE">
            <hardwareInterface>hardware_interface/EffortJointInterface</hardwareInterface>
        </joint>
        <actuator name="RH_HFE_motor">
            <hardwareInterface>hardware_interface/EffortJointInterface</hardwareInterface>
            <mechanicalReduction>1</mechanicalReduction>
        </actuator>
    </transmission>
    <transmission name="trans_RH_KFE">
        <type>transmission_interface/SimpleTransmission</type>
        <joint name="RH_KFE">
            <hardwareInterface>hardware_interface/EffortJointInterface</hardwareInterface>
        </joint>
        <actuator name="RH_KFE_motor">
            <hardwareInterface>hardware_interface/EffortJointInterface</hardwareInterface>
            <mechanicalReduction>1</mechanicalReduction>
        </actuator>
    </transmission>
    <transmission name="trans_Rev3">
        <type>transmission_interface/SimpleTransmission</type>
        <joint name="Rev3">
            <hardwareInterface>hardware_interface/EffortJointInterface</hardwareInterface>
        </joint>
        <actuator name="Rev3_motor">
            <hardwareInterface>hardware_interface/EffortJointInterface</hardwareInterface>
            <mechanicalReduction>1</mechanicalReduction>
        </actuator>
    </transmission>
    <transmission name="trans_Rev6">
        <type>transmission_interface/SimpleTransmission</type>
        <joint name="Rev6">
            <hardwareInterface>hardware_interface/EffortJointInterface</hardwareInterface>
        </joint>
        <actuator name="Rev6_motor">
            <hardwareInterface>hardware_interface/EffortJointInterface</hardwareInterface>
            <mechanicalReduction>1</mechanicalReduction>
        </actuator>
    </transmission>
    <transmission name="trans_Rev7">
        <type>transmission_interface/SimpleTransmission</type>
        <joint name="Rev7">
            <hardwareInterface>hardware_interface/EffortJointInterface</hardwareInterface>
        </joint>
        <actuator name="Rev7_motor">
            <hardwareInterface>hardware_interface/EffortJointInterface</hardwareInterface>
            <mechanicalReduction>1</mechanicalReduction>
        </actuator>
    </transmission>
    <transmission name="trans_Rev8">
        <type>transmission_interface/SimpleTransmission</type>
        <joint name="Rev8">
            <hardwareInterface>hardware_interface/EffortJointInterface</hardwareInterface>
        </joint>
        <actuator name="Rev8_motor">
            <hardwareInterface>hardware_interface/EffortJointInterface</hardwareInterface>
            <mechanicalReduction>1</mechanicalReduction>
        </actuator>
    </transmission>
    <transmission name="trans_Rev9">
        <type>transmission_interface/SimpleTransmission</type>
        <joint name="Rev9">
            <hardwareInterface>hardware_interface/EffortJointInterface</hardwareInterface>
        </joint>
        <actuator name="Rev9_motor">
            <hardwareInterface>hardware_interface/EffortJointInterface</hardwareInterface>
            <mechanicalReduction>1</mechanicalReduction>
        </actuator>
    </transmission>
    <transmission name="trans_Rev10">
        <type>transmission_interface/SimpleTransmission</type>
        <joint name="Rev10">
            <hardwareInterface>hardware_interface/EffortJointInterface</hardwareInterface>
        </joint>
        <actuator name="Rev10_motor">
            <hardwareInterface>hardware_interface/EffortJointInterface</hardwareInterface>
            <mechanicalReduction>1</mechanicalReduction>
        </actuator>
    </transmission>
    <transmission name="trans_Rev11">
        <type>transmission_interface/SimpleTransmission</type>
        <joint name="Rev11">
            <hardwareInterface>hardware_interface/EffortJointInterface</hardwareInterface>
        </joint>
        <actuator name="Rev11_motor">
            <hardwareInterface>hardware_interface/EffortJointInterface</hardwareInterface>
            <mechanicalReduction>1</mechanicalReduction>
        </actuator>
    </transmission>
</robot>

